2018-09-20 14:17:31 WARNING (Recorder) [homeassistant.components.recorder] Ended unfinished session (id=46 from 2018-09-08 23:17:28.799153)
2018-09-20 14:17:41 WARNING (MainThread) [homeassistant.setup] Setup of sensor is taking over 10 seconds.
2018-09-20 14:17:41 WARNING (MainThread) [homeassistant.setup] Setup of notify is taking over 10 seconds.
2018-09-20 14:17:42 WARNING (MainThread) [homeassistant.components.sensor] Setup of platform template is taking over 10 seconds.
2018-09-20 14:17:42 WARNING (MainThread) [homeassistant.components.sensor] Setup of platform bom is taking over 10 seconds.
2018-09-20 14:17:42 ERROR (MainThread) [homeassistant.components.sensor] Error while setting up platform bom
Traceback (most recent call last):
  File "/srv/homeassistant/lib/python3.4/site-packages/requests/packages/urllib3/connection.py", line 141, in _new_conn
    (self.host, self.port), self.timeout, **extra_kw)
  File "/srv/homeassistant/lib/python3.4/site-packages/requests/packages/urllib3/util/connection.py", line 60, in create_connection
    for res in socket.getaddrinfo(host, port, family, socket.SOCK_STREAM):
  File "/usr/lib/python3.4/socket.py", line 530, in getaddrinfo
    for res in _socket.getaddrinfo(host, port, family, type, proto, flags):
socket.gaierror: [Errno -2] Name or service not known

During handling of the above exception, another exception occurred:

Traceback (most recent call last):
  File "/srv/homeassistant/lib/python3.4/site-packages/requests/packages/urllib3/connectionpool.py", line 600, in urlopen
    chunked=chunked)
  File "/srv/homeassistant/lib/python3.4/site-packages/requests/packages/urllib3/connectionpool.py", line 356, in _make_request
    conn.request(method, url, **httplib_request_kw)
  File "/usr/lib/python3.4/http/client.py", line 1090, in request
    self._send_request(method, url, body, headers)
  File "/usr/lib/python3.4/http/client.py", line 1128, in _send_request
    self.endheaders(body)
  File "/usr/lib/python3.4/http/client.py", line 1086, in endheaders
    self._send_output(message_body)
  File "/usr/lib/python3.4/http/client.py", line 924, in _send_output
    self.send(msg)
  File "/usr/lib/python3.4/http/client.py", line 859, in send
    self.connect()
  File "/srv/homeassistant/lib/python3.4/site-packages/requests/packages/urllib3/connection.py", line 166, in connect
    conn = self._new_conn()
  File "/srv/homeassistant/lib/python3.4/site-packages/requests/packages/urllib3/connection.py", line 150, in _new_conn
    self, "Failed to establish a new connection: %s" % e)
requests.packages.urllib3.exceptions.NewConnectionError: <requests.packages.urllib3.connection.HTTPConnection object at 0x6e5ea130>: Failed to establish a new connection: [Errno -2] Name or service not known

During handling of the above exception, another exception occurred:

Traceback (most recent call last):
  File "/srv/homeassistant/lib/python3.4/site-packages/requests/adapters.py", line 438, in send
    timeout=timeout
  File "/srv/homeassistant/lib/python3.4/site-packages/requests/packages/urllib3/connectionpool.py", line 649, in urlopen
    _stacktrace=sys.exc_info()[2])
  File "/srv/homeassistant/lib/python3.4/site-packages/requests/packages/urllib3/util/retry.py", line 388, in increment
    raise MaxRetryError(_pool, url, error or ResponseError(cause))
requests.packages.urllib3.exceptions.MaxRetryError: HTTPConnectionPool(host='www.bom.gov.au', port=80): Max retries exceeded with url: /fwo/IDV60901/IDV60901.95867.json (Caused by NewConnectionError('<requests.packages.urllib3.connection.HTTPConnection object at 0x6e5ea130>: Failed to establish a new connection: [Errno -2] Name or service not known',))

During handling of the above exception, another exception occurred:

Traceback (most recent call last):
  File "/srv/homeassistant/lib/python3.4/site-packages/homeassistant/helpers/entity_component.py", line 164, in _async_setup_platform
    SLOW_SETUP_MAX_WAIT, loop=self.hass.loop)
  File "/usr/lib/python3.4/asyncio/tasks.py", line 372, in wait_for
    return fut.result()
  File "/usr/lib/python3.4/asyncio/futures.py", line 277, in result
    raise self._exception
  File "/usr/lib/python3.4/concurrent/futures/thread.py", line 54, in run
    result = self.fn(*self.args, **self.kwargs)
  File "/srv/homeassistant/lib/python3.4/site-packages/homeassistant/components/sensor/bom.py", line 119, in setup_platform
    rest.update()
  File "/srv/homeassistant/lib/python3.4/site-packages/homeassistant/util/__init__.py", line 306, in wrapper
    result = method(*args, **kwargs)
  File "/srv/homeassistant/lib/python3.4/site-packages/homeassistant/components/sensor/bom.py", line 204, in update
    result = requests.get(self._build_url(), timeout=10).json()
  File "/srv/homeassistant/lib/python3.4/site-packages/requests/api.py", line 72, in get
    return request('get', url, params=params, **kwargs)
  File "/srv/homeassistant/lib/python3.4/site-packages/requests/api.py", line 58, in request
    return session.request(method=method, url=url, **kwargs)
  File "/srv/homeassistant/lib/python3.4/site-packages/requests/sessions.py", line 518, in request
    resp = self.send(prep, **send_kwargs)
  File "/srv/homeassistant/lib/python3.4/site-packages/requests/sessions.py", line 639, in send
    r = adapter.send(request, **kwargs)
  File "/srv/homeassistant/lib/python3.4/site-packages/requests/adapters.py", line 502, in send
    raise ConnectionError(e, request=request)
requests.exceptions.ConnectionError: HTTPConnectionPool(host='www.bom.gov.au', port=80): Max retries exceeded with url: /fwo/IDV60901/IDV60901.95867.json (Caused by NewConnectionError('<requests.packages.urllib3.connection.HTTPConnection object at 0x6e5ea130>: Failed to establish a new connection: [Errno -2] Name or service not known',))
2018-09-20 14:17:43 WARNING (MainThread) [homeassistant.setup] Setup of switch is taking over 10 seconds.
2018-09-20 14:17:43 WARNING (MainThread) [homeassistant.components.switch] Setup of platform template is taking over 10 seconds.
2018-09-20 14:17:43 WARNING (MainThread) [homeassistant.setup] Setup of joaoapps_join is taking over 10 seconds.
2018-09-20 14:17:43 ERROR (MainThread) [homeassistant.setup] Error during setup of component joaoapps_join
Traceback (most recent call last):
  File "/srv/homeassistant/lib/python3.4/site-packages/requests/packages/urllib3/connection.py", line 141, in _new_conn
    (self.host, self.port), self.timeout, **extra_kw)
  File "/srv/homeassistant/lib/python3.4/site-packages/requests/packages/urllib3/util/connection.py", line 60, in create_connection
    for res in socket.getaddrinfo(host, port, family, socket.SOCK_STREAM):
  File "/usr/lib/python3.4/socket.py", line 530, in getaddrinfo
    for res in _socket.getaddrinfo(host, port, family, type, proto, flags):
socket.gaierror: [Errno -2] Name or service not known

During handling of the above exception, another exception occurred:

Traceback (most recent call last):
  File "/srv/homeassistant/lib/python3.4/site-packages/requests/packages/urllib3/connectionpool.py", line 600, in urlopen
    chunked=chunked)
  File "/srv/homeassistant/lib/python3.4/site-packages/requests/packages/urllib3/connectionpool.py", line 345, in _make_request
    self._validate_conn(conn)
  File "/srv/homeassistant/lib/python3.4/site-packages/requests/packages/urllib3/connectionpool.py", line 844, in _validate_conn
    conn.connect()
  File "/srv/homeassistant/lib/python3.4/site-packages/requests/packages/urllib3/connection.py", line 284, in connect
    conn = self._new_conn()
  File "/srv/homeassistant/lib/python3.4/site-packages/requests/packages/urllib3/connection.py", line 150, in _new_conn
    self, "Failed to establish a new connection: %s" % e)
requests.packages.urllib3.exceptions.NewConnectionError: <requests.packages.urllib3.connection.VerifiedHTTPSConnection object at 0x6e57e530>: Failed to establish a new connection: [Errno -2] Name or service not known

During handling of the above exception, another exception occurred:

Traceback (most recent call last):
  File "/srv/homeassistant/lib/python3.4/site-packages/requests/adapters.py", line 438, in send
    timeout=timeout
  File "/srv/homeassistant/lib/python3.4/site-packages/requests/packages/urllib3/connectionpool.py", line 649, in urlopen
    _stacktrace=sys.exc_info()[2])
  File "/srv/homeassistant/lib/python3.4/site-packages/requests/packages/urllib3/util/retry.py", line 388, in increment
    raise MaxRetryError(_pool, url, error or ResponseError(cause))
requests.packages.urllib3.exceptions.MaxRetryError: HTTPSConnectionPool(host='joinjoaomgcd.appspot.com', port=443): Max retries exceeded with url: /_ah/api/registration/v1/listDevices?apikey=a47440872eca4ba08e95295560df3113 (Caused by NewConnectionError('<requests.packages.urllib3.connection.VerifiedHTTPSConnection object at 0x6e57e530>: Failed to establish a new connection: [Errno -2] Name or service not known',))

During handling of the above exception, another exception occurred:

Traceback (most recent call last):
  File "/srv/homeassistant/lib/python3.4/site-packages/homeassistant/setup.py", line 194, in _async_setup_component
    component.setup, hass, processed_config)
  File "/usr/lib/python3.4/asyncio/futures.py", line 388, in __iter__
    yield self  # This tells Task to wait for completion.
  File "/usr/lib/python3.4/asyncio/tasks.py", line 286, in _wakeup
    value = future.result()
  File "/usr/lib/python3.4/asyncio/futures.py", line 277, in result
    raise self._exception
  File "/usr/lib/python3.4/concurrent/futures/thread.py", line 54, in run
    result = self.fn(*self.args, **self.kwargs)
  File "/srv/homeassistant/lib/python3.4/site-packages/homeassistant/components/joaoapps_join.py", line 97, in setup
    if not get_devices(api_key):
  File "/srv/homeassistant/lib/python3.4/site-packages/pyjoin/__init__.py", line 8, in get_devices
    response = requests.get(LIST_URL + api_key).json()
  File "/srv/homeassistant/lib/python3.4/site-packages/requests/api.py", line 72, in get
    return request('get', url, params=params, **kwargs)
  File "/srv/homeassistant/lib/python3.4/site-packages/requests/api.py", line 58, in request
    return session.request(method=method, url=url, **kwargs)
  File "/srv/homeassistant/lib/python3.4/site-packages/requests/sessions.py", line 518, in request
    resp = self.send(prep, **send_kwargs)
  File "/srv/homeassistant/lib/python3.4/site-packages/requests/sessions.py", line 639, in send
    r = adapter.send(request, **kwargs)
  File "/srv/homeassistant/lib/python3.4/site-packages/requests/adapters.py", line 502, in send
    raise ConnectionError(e, request=request)
requests.exceptions.ConnectionError: HTTPSConnectionPool(host='joinjoaomgcd.appspot.com', port=443): Max retries exceeded with url: /_ah/api/registration/v1/listDevices?apikey=a47440872eca4ba08e95295560df3113 (Caused by NewConnectionError('<requests.packages.urllib3.connection.VerifiedHTTPSConnection object at 0x6e57e530>: Failed to establish a new connection: [Errno -2] Name or service not known',))
2018-09-20 14:17:43 WARNING (MainThread) [homeassistant.setup] Setup of wemo is taking over 10 seconds.
2018-09-20 14:17:44 WARNING (MainThread) [homeassistant.components.sensor] Setup of platform yr is taking over 10 seconds.
2018-09-20 14:17:44 WARNING (MainThread) [homeassistant.components.sensor.yr] Retrying in 15 minutes: 
2018-09-20 14:17:44 WARNING (MainThread) [homeassistant.components.sensor] Setup of platform waqi is taking over 10 seconds.
2018-09-20 14:17:44 ERROR (MainThread) [homeassistant.components.sensor.waqi] Failed to connct to WAQI servers.
Traceback (most recent call last):
  File "/srv/homeassistant/lib/python3.4/site-packages/waqiasync/__init__.py", line 48, in _get
    path, params=dict(self._params, **kwargs))
  File "/srv/homeassistant/lib/python3.4/site-packages/aiohttp/helpers.py", line 97, in __iter__
    ret = yield from self._coro
  File "/srv/homeassistant/lib/python3.4/site-packages/aiohttp/client.py", line 231, in _request
    conn = yield from self._connector.connect(req)
  File "/srv/homeassistant/lib/python3.4/site-packages/aiohttp/connector.py", line 378, in connect
    proto = yield from self._create_connection(req)
  File "/srv/homeassistant/lib/python3.4/site-packages/aiohttp/connector.py", line 687, in _create_connection
    _, proto = yield from self._create_direct_connection(req)
  File "/srv/homeassistant/lib/python3.4/site-packages/aiohttp/connector.py", line 698, in _create_direct_connection
    hosts = yield from self._resolve_host(req.url.raw_host, req.port)
  File "/srv/homeassistant/lib/python3.4/site-packages/aiohttp/connector.py", line 669, in _resolve_host
    self._resolver.resolve(host, port, family=self._family)
  File "/srv/homeassistant/lib/python3.4/site-packages/aiohttp/resolver.py", line 31, in resolve
    host, port, type=socket.SOCK_STREAM, family=family)
  File "/usr/lib/python3.4/asyncio/futures.py", line 388, in __iter__
    yield self  # This tells Task to wait for completion.
  File "/usr/lib/python3.4/asyncio/tasks.py", line 286, in _wakeup
    value = future.result()
  File "/usr/lib/python3.4/asyncio/futures.py", line 269, in result
    raise CancelledError
concurrent.futures._base.CancelledError

During handling of the above exception, another exception occurred:

Traceback (most recent call last):
  File "/srv/homeassistant/lib/python3.4/site-packages/homeassistant/components/sensor/waqi.py", line 76, in async_setup_platform
    stations = yield from client.search(location_name)
  File "/srv/homeassistant/lib/python3.4/site-packages/waqiasync/__init__.py", line 32, in search
    return (yield from self._get(SEARCH_URL, keyword=keyword))
  File "/srv/homeassistant/lib/python3.4/site-packages/waqiasync/__init__.py", line 49, in _get
    return (yield from resp.json())['data']
  File "/srv/homeassistant/lib/python3.4/site-packages/async_timeout/__init__.py", line 36, in __exit__
    self._do_exit(exc_type)
  File "/srv/homeassistant/lib/python3.4/site-packages/async_timeout/__init__.py", line 64, in _do_exit
    raise asyncio.TimeoutError
concurrent.futures._base.TimeoutError
2018-09-20 14:17:45 WARNING (MainThread) [homeassistant.components.sensor] Platform waqi not ready yet. Retrying in 30 seconds.
2018-09-20 14:17:45 ERROR (MainThread) [homeassistant.components.notify] Error setting up platform joaoapps_join
Traceback (most recent call last):
  File "/srv/homeassistant/lib/python3.4/site-packages/requests/packages/urllib3/connection.py", line 141, in _new_conn
    (self.host, self.port), self.timeout, **extra_kw)
  File "/srv/homeassistant/lib/python3.4/site-packages/requests/packages/urllib3/util/connection.py", line 60, in create_connection
    for res in socket.getaddrinfo(host, port, family, socket.SOCK_STREAM):
  File "/usr/lib/python3.4/socket.py", line 530, in getaddrinfo
    for res in _socket.getaddrinfo(host, port, family, type, proto, flags):
socket.gaierror: [Errno -2] Name or service not known

During handling of the above exception, another exception occurred:

Traceback (most recent call last):
  File "/srv/homeassistant/lib/python3.4/site-packages/requests/packages/urllib3/connectionpool.py", line 600, in urlopen
    chunked=chunked)
  File "/srv/homeassistant/lib/python3.4/site-packages/requests/packages/urllib3/connectionpool.py", line 345, in _make_request
    self._validate_conn(conn)
  File "/srv/homeassistant/lib/python3.4/site-packages/requests/packages/urllib3/connectionpool.py", line 844, in _validate_conn
    conn.connect()
  File "/srv/homeassistant/lib/python3.4/site-packages/requests/packages/urllib3/connection.py", line 284, in connect
    conn = self._new_conn()
  File "/srv/homeassistant/lib/python3.4/site-packages/requests/packages/urllib3/connection.py", line 150, in _new_conn
    self, "Failed to establish a new connection: %s" % e)
requests.packages.urllib3.exceptions.NewConnectionError: <requests.packages.urllib3.connection.VerifiedHTTPSConnection object at 0x6d3d8670>: Failed to establish a new connection: [Errno -2] Name or service not known

During handling of the above exception, another exception occurred:

Traceback (most recent call last):
  File "/srv/homeassistant/lib/python3.4/site-packages/requests/adapters.py", line 438, in send
    timeout=timeout
  File "/srv/homeassistant/lib/python3.4/site-packages/requests/packages/urllib3/connectionpool.py", line 649, in urlopen
    _stacktrace=sys.exc_info()[2])
  File "/srv/homeassistant/lib/python3.4/site-packages/requests/packages/urllib3/util/retry.py", line 388, in increment
    raise MaxRetryError(_pool, url, error or ResponseError(cause))
requests.packages.urllib3.exceptions.MaxRetryError: HTTPSConnectionPool(host='joinjoaomgcd.appspot.com', port=443): Max retries exceeded with url: /_ah/api/registration/v1/listDevices?apikey=a47440872eca4ba08e95295560df3113 (Caused by NewConnectionError('<requests.packages.urllib3.connection.VerifiedHTTPSConnection object at 0x6d3d8670>: Failed to establish a new connection: [Errno -2] Name or service not known',))

During handling of the above exception, another exception occurred:

Traceback (most recent call last):
  File "/srv/homeassistant/lib/python3.4/site-packages/homeassistant/components/notify/__init__.py", line 101, in async_setup_platform
    platform.get_service, hass, p_config, discovery_info)
  File "/usr/lib/python3.4/asyncio/futures.py", line 388, in __iter__
    yield self  # This tells Task to wait for completion.
  File "/usr/lib/python3.4/asyncio/tasks.py", line 286, in _wakeup
    value = future.result()
  File "/usr/lib/python3.4/asyncio/futures.py", line 277, in result
    raise self._exception
  File "/usr/lib/python3.4/concurrent/futures/thread.py", line 54, in run
    result = self.fn(*self.args, **self.kwargs)
  File "/srv/homeassistant/lib/python3.4/site-packages/homeassistant/components/notify/joaoapps_join.py", line 40, in get_service
    if not get_devices(api_key):
  File "/srv/homeassistant/lib/python3.4/site-packages/pyjoin/__init__.py", line 8, in get_devices
    response = requests.get(LIST_URL + api_key).json()
  File "/srv/homeassistant/lib/python3.4/site-packages/requests/api.py", line 72, in get
    return request('get', url, params=params, **kwargs)
  File "/srv/homeassistant/lib/python3.4/site-packages/requests/api.py", line 58, in request
    return session.request(method=method, url=url, **kwargs)
  File "/srv/homeassistant/lib/python3.4/site-packages/requests/sessions.py", line 518, in request
    resp = self.send(prep, **send_kwargs)
  File "/srv/homeassistant/lib/python3.4/site-packages/requests/sessions.py", line 639, in send
    r = adapter.send(request, **kwargs)
  File "/srv/homeassistant/lib/python3.4/site-packages/requests/adapters.py", line 502, in send
    raise ConnectionError(e, request=request)
requests.exceptions.ConnectionError: HTTPSConnectionPool(host='joinjoaomgcd.appspot.com', port=443): Max retries exceeded with url: /_ah/api/registration/v1/listDevices?apikey=a47440872eca4ba08e95295560df3113 (Caused by NewConnectionError('<requests.packages.urllib3.connection.VerifiedHTTPSConnection object at 0x6d3d8670>: Failed to establish a new connection: [Errno -2] Name or service not known',))
2018-09-20 14:17:45 ERROR (MainThread) [homeassistant.components.notify] Error setting up platform pushbullet
Traceback (most recent call last):
  File "/srv/homeassistant/lib/python3.4/site-packages/requests/packages/urllib3/connection.py", line 141, in _new_conn
    (self.host, self.port), self.timeout, **extra_kw)
  File "/srv/homeassistant/lib/python3.4/site-packages/requests/packages/urllib3/util/connection.py", line 60, in create_connection
    for res in socket.getaddrinfo(host, port, family, socket.SOCK_STREAM):
  File "/usr/lib/python3.4/socket.py", line 530, in getaddrinfo
    for res in _socket.getaddrinfo(host, port, family, type, proto, flags):
socket.gaierror: [Errno -2] Name or service not known

During handling of the above exception, another exception occurred:

Traceback (most recent call last):
  File "/srv/homeassistant/lib/python3.4/site-packages/requests/packages/urllib3/connectionpool.py", line 600, in urlopen
    chunked=chunked)
  File "/srv/homeassistant/lib/python3.4/site-packages/requests/packages/urllib3/connectionpool.py", line 345, in _make_request
    self._validate_conn(conn)
  File "/srv/homeassistant/lib/python3.4/site-packages/requests/packages/urllib3/connectionpool.py", line 844, in _validate_conn
    conn.connect()
  File "/srv/homeassistant/lib/python3.4/site-packages/requests/packages/urllib3/connection.py", line 284, in connect
    conn = self._new_conn()
  File "/srv/homeassistant/lib/python3.4/site-packages/requests/packages/urllib3/connection.py", line 150, in _new_conn
    self, "Failed to establish a new connection: %s" % e)
requests.packages.urllib3.exceptions.NewConnectionError: <requests.packages.urllib3.connection.VerifiedHTTPSConnection object at 0x6d3fb130>: Failed to establish a new connection: [Errno -2] Name or service not known

During handling of the above exception, another exception occurred:

Traceback (most recent call last):
  File "/srv/homeassistant/lib/python3.4/site-packages/requests/adapters.py", line 438, in send
    timeout=timeout
  File "/srv/homeassistant/lib/python3.4/site-packages/requests/packages/urllib3/connectionpool.py", line 649, in urlopen
    _stacktrace=sys.exc_info()[2])
  File "/srv/homeassistant/lib/python3.4/site-packages/requests/packages/urllib3/util/retry.py", line 388, in increment
    raise MaxRetryError(_pool, url, error or ResponseError(cause))
requests.packages.urllib3.exceptions.MaxRetryError: HTTPSConnectionPool(host='api.pushbullet.com', port=443): Max retries exceeded with url: /v2/devices (Caused by NewConnectionError('<requests.packages.urllib3.connection.VerifiedHTTPSConnection object at 0x6d3fb130>: Failed to establish a new connection: [Errno -2] Name or service not known',))

During handling of the above exception, another exception occurred:

Traceback (most recent call last):
  File "/srv/homeassistant/lib/python3.4/site-packages/homeassistant/components/notify/__init__.py", line 101, in async_setup_platform
    platform.get_service, hass, p_config, discovery_info)
  File "/usr/lib/python3.4/asyncio/futures.py", line 388, in __iter__
    yield self  # This tells Task to wait for completion.
  File "/usr/lib/python3.4/asyncio/tasks.py", line 286, in _wakeup
    value = future.result()
  File "/usr/lib/python3.4/asyncio/futures.py", line 277, in result
    raise self._exception
  File "/usr/lib/python3.4/concurrent/futures/thread.py", line 54, in run
    result = self.fn(*self.args, **self.kwargs)
  File "/srv/homeassistant/lib/python3.4/site-packages/homeassistant/components/notify/pushbullet.py", line 38, in get_service
    pushbullet = PushBullet(config[CONF_API_KEY])
  File "/srv/homeassistant/lib/python3.4/site-packages/pushbullet/pushbullet.py", line 43, in __init__
    self.refresh()
  File "/srv/homeassistant/lib/python3.4/site-packages/pushbullet/pushbullet.py", line 381, in refresh
    self._load_devices()
  File "/srv/homeassistant/lib/python3.4/site-packages/pushbullet/pushbullet.py", line 78, in _load_devices
    resp_dict = self._get_data(self.DEVICES_URL)
  File "/srv/homeassistant/lib/python3.4/site-packages/pushbullet/pushbullet.py", line 64, in _get_data
    resp = self._session.get(url)
  File "/srv/homeassistant/lib/python3.4/site-packages/requests/sessions.py", line 531, in get
    return self.request('GET', url, **kwargs)
  File "/srv/homeassistant/lib/python3.4/site-packages/requests/sessions.py", line 518, in request
    resp = self.send(prep, **send_kwargs)
  File "/srv/homeassistant/lib/python3.4/site-packages/requests/sessions.py", line 639, in send
    r = adapter.send(request, **kwargs)
  File "/srv/homeassistant/lib/python3.4/site-packages/requests/adapters.py", line 502, in send
    raise ConnectionError(e, request=request)
requests.exceptions.ConnectionError: HTTPSConnectionPool(host='api.pushbullet.com', port=443): Max retries exceeded with url: /v2/devices (Caused by NewConnectionError('<requests.packages.urllib3.connection.VerifiedHTTPSConnection object at 0x6d3fb130>: Failed to establish a new connection: [Errno -2] Name or service not known',))
2018-09-20 14:17:49 WARNING (Thread-4) [homeassistant.components.wemo] Unable to probe wemo at 192.168.1.4
2018-09-20 15:31:40 WARNING (Thread-8) [netdisco.ssdp] Found malformed XML at http://192.168.86.150:9080: status=ok
2018-09-20 15:31:56 WARNING (MainThread) [homeassistant.components.media_player] Setup of platform cast is taking over 10 seconds.
2018-09-20 15:31:56 ERROR (Thread-7) [pychromecast.socket_client] Failed to connect, retrying in 5.0s
2018-09-20 15:31:56 ERROR (Thread-3) [pychromecast.socket_client] Failed to connect, retrying in 5.0s
2018-09-20 15:31:56 ERROR (Thread-11) [pychromecast.socket_client] Failed to connect, retrying in 5.0s
2018-09-20 15:31:56 WARNING (MainThread) [homeassistant.components.media_player] Setup of platform cast is taking over 10 seconds.
2018-09-20 15:31:56 WARNING (MainThread) [homeassistant.components.media_player] Setup of platform cast is taking over 10 seconds.
2018-09-20 15:32:46 ERROR (MainThread) [homeassistant.components.media_player] Setup of platform cast is taking longer than 60 seconds. Startup will proceed without waiting any longer.
2018-09-20 15:32:46 ERROR (MainThread) [homeassistant.components.media_player] Setup of platform cast is taking longer than 60 seconds. Startup will proceed without waiting any longer.
2018-09-20 15:32:46 ERROR (MainThread) [homeassistant.components.media_player] Setup of platform cast is taking longer than 60 seconds. Startup will proceed without waiting any longer.
2018-09-20 16:32:24 WARNING (MainThread) [homeassistant.helpers.entity] Update of media_player.roku_yl006v812385 is taking over 10 seconds
2018-09-20 16:32:25 WARNING (MainThread) [homeassistant.components.media_player] Updating roku media_player took longer than the scheduled update interval 0:00:10
2018-09-20 16:32:36 WARNING (MainThread) [homeassistant.components.media_player] Updating roku media_player took longer than the scheduled update interval 0:00:10
2018-09-20 17:06:48 WARNING (MainThread) [homeassistant.helpers.entity] Update of sensor.waqi_box_hill_australia is taking over 10 seconds
2018-09-20 17:06:48 ERROR (MainThread) [homeassistant.helpers.entity] Update for sensor.waqi_box_hill_australia fails
Traceback (most recent call last):
  File "/srv/homeassistant/lib/python3.4/site-packages/waqiasync/__init__.py", line 48, in _get
    path, params=dict(self._params, **kwargs))
  File "/srv/homeassistant/lib/python3.4/site-packages/aiohttp/helpers.py", line 97, in __iter__
    ret = yield from self._coro
  File "/srv/homeassistant/lib/python3.4/site-packages/aiohttp/client.py", line 241, in _request
    yield from resp.start(conn, read_until_eof)
  File "/srv/homeassistant/lib/python3.4/site-packages/aiohttp/client_reqrep.py", line 559, in start
    (message, payload) = yield from self._protocol.read()
  File "/srv/homeassistant/lib/python3.4/site-packages/aiohttp/streams.py", line 509, in read
    yield from self._waiter
  File "/usr/lib/python3.4/asyncio/futures.py", line 388, in __iter__
    yield self  # This tells Task to wait for completion.
  File "/usr/lib/python3.4/asyncio/tasks.py", line 286, in _wakeup
    value = future.result()
  File "/usr/lib/python3.4/asyncio/futures.py", line 269, in result
    raise CancelledError
concurrent.futures._base.CancelledError

During handling of the above exception, another exception occurred:

Traceback (most recent call last):
  File "/srv/homeassistant/lib/python3.4/site-packages/homeassistant/helpers/entity.py", line 223, in async_update_ha_state
    yield from self.async_update()
  File "/srv/homeassistant/lib/python3.4/site-packages/homeassistant/components/sensor/waqi.py", line 167, in async_update
    result = yield from self._client.get_station_by_number(self.uid)
  File "/srv/homeassistant/lib/python3.4/site-packages/waqiasync/__init__.py", line 42, in get_station_by_number
    return (yield from self._get(FEED_NUMBER_URL.format(number)))
  File "/srv/homeassistant/lib/python3.4/site-packages/waqiasync/__init__.py", line 49, in _get
    return (yield from resp.json())['data']
  File "/srv/homeassistant/lib/python3.4/site-packages/async_timeout/__init__.py", line 36, in __exit__
    self._do_exit(exc_type)
  File "/srv/homeassistant/lib/python3.4/site-packages/async_timeout/__init__.py", line 64, in _do_exit
    raise asyncio.TimeoutError
concurrent.futures._base.TimeoutError
2018-09-20 18:27:04 WARNING (MainThread) [homeassistant.helpers.entity] Update of sensor.waqi_box_hill_australia is taking over 10 seconds
2018-09-20 18:27:04 ERROR (MainThread) [homeassistant.helpers.entity] Update for sensor.waqi_box_hill_australia fails
Traceback (most recent call last):
  File "/srv/homeassistant/lib/python3.4/site-packages/waqiasync/__init__.py", line 48, in _get
    path, params=dict(self._params, **kwargs))
  File "/srv/homeassistant/lib/python3.4/site-packages/aiohttp/helpers.py", line 97, in __iter__
    ret = yield from self._coro
  File "/srv/homeassistant/lib/python3.4/site-packages/aiohttp/client.py", line 231, in _request
    conn = yield from self._connector.connect(req)
  File "/srv/homeassistant/lib/python3.4/site-packages/aiohttp/connector.py", line 378, in connect
    proto = yield from self._create_connection(req)
  File "/srv/homeassistant/lib/python3.4/site-packages/aiohttp/connector.py", line 687, in _create_connection
    _, proto = yield from self._create_direct_connection(req)
  File "/srv/homeassistant/lib/python3.4/site-packages/aiohttp/connector.py", line 710, in _create_direct_connection
    local_addr=self._local_addr)
  File "/usr/lib/python3.4/asyncio/base_events.py", line 557, in create_connection
    yield from self.sock_connect(sock, address)
  File "/usr/lib/python3.4/asyncio/futures.py", line 388, in __iter__
    yield self  # This tells Task to wait for completion.
  File "/usr/lib/python3.4/asyncio/tasks.py", line 286, in _wakeup
    value = future.result()
  File "/usr/lib/python3.4/asyncio/futures.py", line 269, in result
    raise CancelledError
concurrent.futures._base.CancelledError

During handling of the above exception, another exception occurred:

Traceback (most recent call last):
  File "/srv/homeassistant/lib/python3.4/site-packages/homeassistant/helpers/entity.py", line 223, in async_update_ha_state
    yield from self.async_update()
  File "/srv/homeassistant/lib/python3.4/site-packages/homeassistant/components/sensor/waqi.py", line 167, in async_update
    result = yield from self._client.get_station_by_number(self.uid)
  File "/srv/homeassistant/lib/python3.4/site-packages/waqiasync/__init__.py", line 42, in get_station_by_number
    return (yield from self._get(FEED_NUMBER_URL.format(number)))
  File "/srv/homeassistant/lib/python3.4/site-packages/waqiasync/__init__.py", line 49, in _get
    return (yield from resp.json())['data']
  File "/srv/homeassistant/lib/python3.4/site-packages/async_timeout/__init__.py", line 36, in __exit__
    self._do_exit(exc_type)
  File "/srv/homeassistant/lib/python3.4/site-packages/async_timeout/__init__.py", line 64, in _do_exit
    raise asyncio.TimeoutError
concurrent.futures._base.TimeoutError
2018-09-21 02:28:40 WARNING (MainThread) [homeassistant.helpers.entity] Update of sensor.waqi_box_hill_australia is taking over 10 seconds
2018-09-21 02:28:40 ERROR (MainThread) [homeassistant.helpers.entity] Update for sensor.waqi_box_hill_australia fails
Traceback (most recent call last):
  File "/srv/homeassistant/lib/python3.4/site-packages/waqiasync/__init__.py", line 48, in _get
    path, params=dict(self._params, **kwargs))
  File "/srv/homeassistant/lib/python3.4/site-packages/aiohttp/helpers.py", line 97, in __iter__
    ret = yield from self._coro
  File "/srv/homeassistant/lib/python3.4/site-packages/aiohttp/client.py", line 231, in _request
    conn = yield from self._connector.connect(req)
  File "/srv/homeassistant/lib/python3.4/site-packages/aiohttp/connector.py", line 378, in connect
    proto = yield from self._create_connection(req)
  File "/srv/homeassistant/lib/python3.4/site-packages/aiohttp/connector.py", line 687, in _create_connection
    _, proto = yield from self._create_direct_connection(req)
  File "/srv/homeassistant/lib/python3.4/site-packages/aiohttp/connector.py", line 710, in _create_direct_connection
    local_addr=self._local_addr)
  File "/usr/lib/python3.4/asyncio/base_events.py", line 588, in create_connection
    sock, protocol_factory, ssl, server_hostname)
  File "/usr/lib/python3.4/asyncio/base_events.py", line 610, in _create_connection_transport
    yield from waiter
  File "/usr/lib/python3.4/asyncio/futures.py", line 388, in __iter__
    yield self  # This tells Task to wait for completion.
  File "/usr/lib/python3.4/asyncio/tasks.py", line 286, in _wakeup
    value = future.result()
  File "/usr/lib/python3.4/asyncio/futures.py", line 269, in result
    raise CancelledError
concurrent.futures._base.CancelledError

During handling of the above exception, another exception occurred:

Traceback (most recent call last):
  File "/srv/homeassistant/lib/python3.4/site-packages/homeassistant/helpers/entity.py", line 223, in async_update_ha_state
    yield from self.async_update()
  File "/srv/homeassistant/lib/python3.4/site-packages/homeassistant/components/sensor/waqi.py", line 167, in async_update
    result = yield from self._client.get_station_by_number(self.uid)
  File "/srv/homeassistant/lib/python3.4/site-packages/waqiasync/__init__.py", line 42, in get_station_by_number
    return (yield from self._get(FEED_NUMBER_URL.format(number)))
  File "/srv/homeassistant/lib/python3.4/site-packages/waqiasync/__init__.py", line 49, in _get
    return (yield from resp.json())['data']
  File "/srv/homeassistant/lib/python3.4/site-packages/async_timeout/__init__.py", line 36, in __exit__
    self._do_exit(exc_type)
  File "/srv/homeassistant/lib/python3.4/site-packages/async_timeout/__init__.py", line 64, in _do_exit
    raise asyncio.TimeoutError
concurrent.futures._base.TimeoutError
2018-09-21 04:08:51 ERROR (MainThread) [homeassistant.helpers.entity] Update for sensor.waqi_box_hill_australia fails
Traceback (most recent call last):
  File "/srv/homeassistant/lib/python3.4/site-packages/homeassistant/helpers/entity.py", line 223, in async_update_ha_state
    yield from self.async_update()
  File "/srv/homeassistant/lib/python3.4/site-packages/homeassistant/components/sensor/waqi.py", line 167, in async_update
    result = yield from self._client.get_station_by_number(self.uid)
  File "/srv/homeassistant/lib/python3.4/site-packages/waqiasync/__init__.py", line 42, in get_station_by_number
    return (yield from self._get(FEED_NUMBER_URL.format(number)))
  File "/srv/homeassistant/lib/python3.4/site-packages/waqiasync/__init__.py", line 49, in _get
    return (yield from resp.json())['data']
  File "/srv/homeassistant/lib/python3.4/site-packages/aiohttp/client_reqrep.py", line 730, in json
    headers=self.headers)
aiohttp.client_exceptions.ClientResponseError: 0, message='Attempt to decode JSON with unexpected mimetype: text/html'
2018-09-21 05:54:20 WARNING (MainThread) [homeassistant.helpers.entity] Update of sensor.waqi_box_hill_australia is taking over 10 seconds
2018-09-21 05:54:20 ERROR (MainThread) [homeassistant.helpers.entity] Update for sensor.waqi_box_hill_australia fails
Traceback (most recent call last):
  File "/srv/homeassistant/lib/python3.4/site-packages/waqiasync/__init__.py", line 48, in _get
    path, params=dict(self._params, **kwargs))
  File "/srv/homeassistant/lib/python3.4/site-packages/aiohttp/helpers.py", line 97, in __iter__
    ret = yield from self._coro
  File "/srv/homeassistant/lib/python3.4/site-packages/aiohttp/client.py", line 231, in _request
    conn = yield from self._connector.connect(req)
  File "/srv/homeassistant/lib/python3.4/site-packages/aiohttp/connector.py", line 378, in connect
    proto = yield from self._create_connection(req)
  File "/srv/homeassistant/lib/python3.4/site-packages/aiohttp/connector.py", line 687, in _create_connection
    _, proto = yield from self._create_direct_connection(req)
  File "/srv/homeassistant/lib/python3.4/site-packages/aiohttp/connector.py", line 710, in _create_direct_connection
    local_addr=self._local_addr)
  File "/usr/lib/python3.4/asyncio/base_events.py", line 557, in create_connection
    yield from self.sock_connect(sock, address)
  File "/usr/lib/python3.4/asyncio/futures.py", line 388, in __iter__
    yield self  # This tells Task to wait for completion.
  File "/usr/lib/python3.4/asyncio/tasks.py", line 286, in _wakeup
    value = future.result()
  File "/usr/lib/python3.4/asyncio/futures.py", line 269, in result
    raise CancelledError
concurrent.futures._base.CancelledError

During handling of the above exception, another exception occurred:

Traceback (most recent call last):
  File "/srv/homeassistant/lib/python3.4/site-packages/homeassistant/helpers/entity.py", line 223, in async_update_ha_state
    yield from self.async_update()
  File "/srv/homeassistant/lib/python3.4/site-packages/homeassistant/components/sensor/waqi.py", line 167, in async_update
    result = yield from self._client.get_station_by_number(self.uid)
  File "/srv/homeassistant/lib/python3.4/site-packages/waqiasync/__init__.py", line 42, in get_station_by_number
    return (yield from self._get(FEED_NUMBER_URL.format(number)))
  File "/srv/homeassistant/lib/python3.4/site-packages/waqiasync/__init__.py", line 49, in _get
    return (yield from resp.json())['data']
  File "/srv/homeassistant/lib/python3.4/site-packages/async_timeout/__init__.py", line 36, in __exit__
    self._do_exit(exc_type)
  File "/srv/homeassistant/lib/python3.4/site-packages/async_timeout/__init__.py", line 64, in _do_exit
    raise asyncio.TimeoutError
concurrent.futures._base.TimeoutError
2018-09-21 07:04:30 ERROR (MainThread) [homeassistant.helpers.entity] Update for sensor.waqi_box_hill_australia fails
Traceback (most recent call last):
  File "/srv/homeassistant/lib/python3.4/site-packages/homeassistant/helpers/entity.py", line 223, in async_update_ha_state
    yield from self.async_update()
  File "/srv/homeassistant/lib/python3.4/site-packages/homeassistant/components/sensor/waqi.py", line 167, in async_update
    result = yield from self._client.get_station_by_number(self.uid)
  File "/srv/homeassistant/lib/python3.4/site-packages/waqiasync/__init__.py", line 42, in get_station_by_number
    return (yield from self._get(FEED_NUMBER_URL.format(number)))
  File "/srv/homeassistant/lib/python3.4/site-packages/waqiasync/__init__.py", line 49, in _get
    return (yield from resp.json())['data']
  File "/srv/homeassistant/lib/python3.4/site-packages/aiohttp/client_reqrep.py", line 730, in json
    headers=self.headers)
aiohttp.client_exceptions.ClientResponseError: 0, message='Attempt to decode JSON with unexpected mimetype: text/html'
2018-09-21 08:07:55 ERROR (MainThread) [homeassistant.core] Timer got out of sync. Resetting
2018-09-21 10:55:16 ERROR (MainThread) [homeassistant.helpers.entity] Update for sensor.waqi_box_hill_australia fails
Traceback (most recent call last):
  File "/srv/homeassistant/lib/python3.4/site-packages/homeassistant/helpers/entity.py", line 223, in async_update_ha_state
    yield from self.async_update()
  File "/srv/homeassistant/lib/python3.4/site-packages/homeassistant/components/sensor/waqi.py", line 167, in async_update
    result = yield from self._client.get_station_by_number(self.uid)
  File "/srv/homeassistant/lib/python3.4/site-packages/waqiasync/__init__.py", line 42, in get_station_by_number
    return (yield from self._get(FEED_NUMBER_URL.format(number)))
  File "/srv/homeassistant/lib/python3.4/site-packages/waqiasync/__init__.py", line 49, in _get
    return (yield from resp.json())['data']
  File "/srv/homeassistant/lib/python3.4/site-packages/aiohttp/client_reqrep.py", line 730, in json
    headers=self.headers)
aiohttp.client_exceptions.ClientResponseError: 0, message='Attempt to decode JSON with unexpected mimetype: text/html'
2018-09-21 13:00:43 WARNING (MainThread) [homeassistant.helpers.entity] Update of sensor.waqi_box_hill_australia is taking over 10 seconds
2018-09-21 13:00:43 ERROR (MainThread) [homeassistant.helpers.entity] Update for sensor.waqi_box_hill_australia fails
Traceback (most recent call last):
  File "/srv/homeassistant/lib/python3.4/site-packages/waqiasync/__init__.py", line 48, in _get
    path, params=dict(self._params, **kwargs))
  File "/srv/homeassistant/lib/python3.4/site-packages/aiohttp/helpers.py", line 97, in __iter__
    ret = yield from self._coro
  File "/srv/homeassistant/lib/python3.4/site-packages/aiohttp/client.py", line 231, in _request
    conn = yield from self._connector.connect(req)
  File "/srv/homeassistant/lib/python3.4/site-packages/aiohttp/connector.py", line 378, in connect
    proto = yield from self._create_connection(req)
  File "/srv/homeassistant/lib/python3.4/site-packages/aiohttp/connector.py", line 687, in _create_connection
    _, proto = yield from self._create_direct_connection(req)
  File "/srv/homeassistant/lib/python3.4/site-packages/aiohttp/connector.py", line 710, in _create_direct_connection
    local_addr=self._local_addr)
  File "/usr/lib/python3.4/asyncio/base_events.py", line 557, in create_connection
    yield from self.sock_connect(sock, address)
  File "/usr/lib/python3.4/asyncio/futures.py", line 388, in __iter__
    yield self  # This tells Task to wait for completion.
  File "/usr/lib/python3.4/asyncio/tasks.py", line 286, in _wakeup
    value = future.result()
  File "/usr/lib/python3.4/asyncio/futures.py", line 269, in result
    raise CancelledError
concurrent.futures._base.CancelledError

During handling of the above exception, another exception occurred:

Traceback (most recent call last):
  File "/srv/homeassistant/lib/python3.4/site-packages/homeassistant/helpers/entity.py", line 223, in async_update_ha_state
    yield from self.async_update()
  File "/srv/homeassistant/lib/python3.4/site-packages/homeassistant/components/sensor/waqi.py", line 167, in async_update
    result = yield from self._client.get_station_by_number(self.uid)
  File "/srv/homeassistant/lib/python3.4/site-packages/waqiasync/__init__.py", line 42, in get_station_by_number
    return (yield from self._get(FEED_NUMBER_URL.format(number)))
  File "/srv/homeassistant/lib/python3.4/site-packages/waqiasync/__init__.py", line 49, in _get
    return (yield from resp.json())['data']
  File "/srv/homeassistant/lib/python3.4/site-packages/async_timeout/__init__.py", line 36, in __exit__
    self._do_exit(exc_type)
  File "/srv/homeassistant/lib/python3.4/site-packages/async_timeout/__init__.py", line 64, in _do_exit
    raise asyncio.TimeoutError
concurrent.futures._base.TimeoutError
2018-09-21 13:20:47 WARNING (MainThread) [homeassistant.helpers.entity] Update of sensor.waqi_box_hill_australia is taking over 10 seconds
2018-09-21 13:20:47 ERROR (MainThread) [homeassistant.helpers.entity] Update for sensor.waqi_box_hill_australia fails
Traceback (most recent call last):
  File "/srv/homeassistant/lib/python3.4/site-packages/waqiasync/__init__.py", line 48, in _get
    path, params=dict(self._params, **kwargs))
  File "/srv/homeassistant/lib/python3.4/site-packages/aiohttp/helpers.py", line 97, in __iter__
    ret = yield from self._coro
  File "/srv/homeassistant/lib/python3.4/site-packages/aiohttp/client.py", line 241, in _request
    yield from resp.start(conn, read_until_eof)
  File "/srv/homeassistant/lib/python3.4/site-packages/aiohttp/client_reqrep.py", line 559, in start
    (message, payload) = yield from self._protocol.read()
  File "/srv/homeassistant/lib/python3.4/site-packages/aiohttp/streams.py", line 509, in read
    yield from self._waiter
  File "/usr/lib/python3.4/asyncio/futures.py", line 388, in __iter__
    yield self  # This tells Task to wait for completion.
  File "/usr/lib/python3.4/asyncio/tasks.py", line 286, in _wakeup
    value = future.result()
  File "/usr/lib/python3.4/asyncio/futures.py", line 269, in result
    raise CancelledError
concurrent.futures._base.CancelledError

During handling of the above exception, another exception occurred:

Traceback (most recent call last):
  File "/srv/homeassistant/lib/python3.4/site-packages/homeassistant/helpers/entity.py", line 223, in async_update_ha_state
    yield from self.async_update()
  File "/srv/homeassistant/lib/python3.4/site-packages/homeassistant/components/sensor/waqi.py", line 167, in async_update
    result = yield from self._client.get_station_by_number(self.uid)
  File "/srv/homeassistant/lib/python3.4/site-packages/waqiasync/__init__.py", line 42, in get_station_by_number
    return (yield from self._get(FEED_NUMBER_URL.format(number)))
  File "/srv/homeassistant/lib/python3.4/site-packages/waqiasync/__init__.py", line 49, in _get
    return (yield from resp.json())['data']
  File "/srv/homeassistant/lib/python3.4/site-packages/async_timeout/__init__.py", line 36, in __exit__
    self._do_exit(exc_type)
  File "/srv/homeassistant/lib/python3.4/site-packages/async_timeout/__init__.py", line 64, in _do_exit
    raise asyncio.TimeoutError
concurrent.futures._base.TimeoutError
2018-09-21 14:20:59 WARNING (MainThread) [homeassistant.helpers.entity] Update of sensor.waqi_box_hill_australia is taking over 10 seconds
2018-09-21 14:20:59 ERROR (MainThread) [homeassistant.helpers.entity] Update for sensor.waqi_box_hill_australia fails
Traceback (most recent call last):
  File "/srv/homeassistant/lib/python3.4/site-packages/waqiasync/__init__.py", line 48, in _get
    path, params=dict(self._params, **kwargs))
  File "/srv/homeassistant/lib/python3.4/site-packages/aiohttp/helpers.py", line 97, in __iter__
    ret = yield from self._coro
  File "/srv/homeassistant/lib/python3.4/site-packages/aiohttp/client.py", line 241, in _request
    yield from resp.start(conn, read_until_eof)
  File "/srv/homeassistant/lib/python3.4/site-packages/aiohttp/client_reqrep.py", line 559, in start
    (message, payload) = yield from self._protocol.read()
  File "/srv/homeassistant/lib/python3.4/site-packages/aiohttp/streams.py", line 509, in read
    yield from self._waiter
  File "/usr/lib/python3.4/asyncio/futures.py", line 388, in __iter__
    yield self  # This tells Task to wait for completion.
  File "/usr/lib/python3.4/asyncio/tasks.py", line 286, in _wakeup
    value = future.result()
  File "/usr/lib/python3.4/asyncio/futures.py", line 269, in result
    raise CancelledError
concurrent.futures._base.CancelledError

During handling of the above exception, another exception occurred:

Traceback (most recent call last):
  File "/srv/homeassistant/lib/python3.4/site-packages/homeassistant/helpers/entity.py", line 223, in async_update_ha_state
    yield from self.async_update()
  File "/srv/homeassistant/lib/python3.4/site-packages/homeassistant/components/sensor/waqi.py", line 167, in async_update
    result = yield from self._client.get_station_by_number(self.uid)
  File "/srv/homeassistant/lib/python3.4/site-packages/waqiasync/__init__.py", line 42, in get_station_by_number
    return (yield from self._get(FEED_NUMBER_URL.format(number)))
  File "/srv/homeassistant/lib/python3.4/site-packages/waqiasync/__init__.py", line 49, in _get
    return (yield from resp.json())['data']
  File "/srv/homeassistant/lib/python3.4/site-packages/async_timeout/__init__.py", line 36, in __exit__
    self._do_exit(exc_type)
  File "/srv/homeassistant/lib/python3.4/site-packages/async_timeout/__init__.py", line 64, in _do_exit
    raise asyncio.TimeoutError
concurrent.futures._base.TimeoutError
2018-09-21 14:51:04 ERROR (MainThread) [homeassistant.helpers.entity] Update for sensor.waqi_box_hill_australia fails
Traceback (most recent call last):
  File "/srv/homeassistant/lib/python3.4/site-packages/homeassistant/helpers/entity.py", line 223, in async_update_ha_state
    yield from self.async_update()
  File "/srv/homeassistant/lib/python3.4/site-packages/homeassistant/components/sensor/waqi.py", line 167, in async_update
    result = yield from self._client.get_station_by_number(self.uid)
  File "/srv/homeassistant/lib/python3.4/site-packages/waqiasync/__init__.py", line 42, in get_station_by_number
    return (yield from self._get(FEED_NUMBER_URL.format(number)))
  File "/srv/homeassistant/lib/python3.4/site-packages/waqiasync/__init__.py", line 49, in _get
    return (yield from resp.json())['data']
  File "/srv/homeassistant/lib/python3.4/site-packages/aiohttp/client_reqrep.py", line 730, in json
    headers=self.headers)
aiohttp.client_exceptions.ClientResponseError: 0, message='Attempt to decode JSON with unexpected mimetype: text/html'
2018-09-21 15:11:09 WARNING (MainThread) [homeassistant.helpers.entity] Update of sensor.waqi_box_hill_australia is taking over 10 seconds
2018-09-21 15:11:09 ERROR (MainThread) [homeassistant.helpers.entity] Update for sensor.waqi_box_hill_australia fails
Traceback (most recent call last):
  File "/srv/homeassistant/lib/python3.4/site-packages/waqiasync/__init__.py", line 48, in _get
    path, params=dict(self._params, **kwargs))
  File "/srv/homeassistant/lib/python3.4/site-packages/aiohttp/helpers.py", line 97, in __iter__
    ret = yield from self._coro
  File "/srv/homeassistant/lib/python3.4/site-packages/aiohttp/client.py", line 241, in _request
    yield from resp.start(conn, read_until_eof)
  File "/srv/homeassistant/lib/python3.4/site-packages/aiohttp/client_reqrep.py", line 559, in start
    (message, payload) = yield from self._protocol.read()
  File "/srv/homeassistant/lib/python3.4/site-packages/aiohttp/streams.py", line 509, in read
    yield from self._waiter
  File "/usr/lib/python3.4/asyncio/futures.py", line 388, in __iter__
    yield self  # This tells Task to wait for completion.
  File "/usr/lib/python3.4/asyncio/tasks.py", line 286, in _wakeup
    value = future.result()
  File "/usr/lib/python3.4/asyncio/futures.py", line 269, in result
    raise CancelledError
concurrent.futures._base.CancelledError

During handling of the above exception, another exception occurred:

Traceback (most recent call last):
  File "/srv/homeassistant/lib/python3.4/site-packages/homeassistant/helpers/entity.py", line 223, in async_update_ha_state
    yield from self.async_update()
  File "/srv/homeassistant/lib/python3.4/site-packages/homeassistant/components/sensor/waqi.py", line 167, in async_update
    result = yield from self._client.get_station_by_number(self.uid)
  File "/srv/homeassistant/lib/python3.4/site-packages/waqiasync/__init__.py", line 42, in get_station_by_number
    return (yield from self._get(FEED_NUMBER_URL.format(number)))
  File "/srv/homeassistant/lib/python3.4/site-packages/waqiasync/__init__.py", line 49, in _get
    return (yield from resp.json())['data']
  File "/srv/homeassistant/lib/python3.4/site-packages/async_timeout/__init__.py", line 36, in __exit__
    self._do_exit(exc_type)
  File "/srv/homeassistant/lib/python3.4/site-packages/async_timeout/__init__.py", line 64, in _do_exit
    raise asyncio.TimeoutError
concurrent.futures._base.TimeoutError
2018-09-21 15:51:17 WARNING (MainThread) [homeassistant.helpers.entity] Update of sensor.waqi_box_hill_australia is taking over 10 seconds
2018-09-21 15:51:17 ERROR (MainThread) [homeassistant.helpers.entity] Update for sensor.waqi_box_hill_australia fails
Traceback (most recent call last):
  File "/srv/homeassistant/lib/python3.4/site-packages/waqiasync/__init__.py", line 48, in _get
    path, params=dict(self._params, **kwargs))
  File "/srv/homeassistant/lib/python3.4/site-packages/aiohttp/helpers.py", line 97, in __iter__
    ret = yield from self._coro
  File "/srv/homeassistant/lib/python3.4/site-packages/aiohttp/client.py", line 241, in _request
    yield from resp.start(conn, read_until_eof)
  File "/srv/homeassistant/lib/python3.4/site-packages/aiohttp/client_reqrep.py", line 559, in start
    (message, payload) = yield from self._protocol.read()
  File "/srv/homeassistant/lib/python3.4/site-packages/aiohttp/streams.py", line 509, in read
    yield from self._waiter
  File "/usr/lib/python3.4/asyncio/futures.py", line 388, in __iter__
    yield self  # This tells Task to wait for completion.
  File "/usr/lib/python3.4/asyncio/tasks.py", line 286, in _wakeup
    value = future.result()
  File "/usr/lib/python3.4/asyncio/futures.py", line 269, in result
    raise CancelledError
concurrent.futures._base.CancelledError

During handling of the above exception, another exception occurred:

Traceback (most recent call last):
  File "/srv/homeassistant/lib/python3.4/site-packages/homeassistant/helpers/entity.py", line 223, in async_update_ha_state
    yield from self.async_update()
  File "/srv/homeassistant/lib/python3.4/site-packages/homeassistant/components/sensor/waqi.py", line 167, in async_update
    result = yield from self._client.get_station_by_number(self.uid)
  File "/srv/homeassistant/lib/python3.4/site-packages/waqiasync/__init__.py", line 42, in get_station_by_number
    return (yield from self._get(FEED_NUMBER_URL.format(number)))
  File "/srv/homeassistant/lib/python3.4/site-packages/waqiasync/__init__.py", line 49, in _get
    return (yield from resp.json())['data']
  File "/srv/homeassistant/lib/python3.4/site-packages/async_timeout/__init__.py", line 36, in __exit__
    self._do_exit(exc_type)
  File "/srv/homeassistant/lib/python3.4/site-packages/async_timeout/__init__.py", line 64, in _do_exit
    raise asyncio.TimeoutError
concurrent.futures._base.TimeoutError
2018-09-21 15:56:18 WARNING (MainThread) [homeassistant.helpers.entity] Update of sensor.waqi_box_hill_australia is taking over 10 seconds
2018-09-21 15:56:18 ERROR (MainThread) [homeassistant.helpers.entity] Update for sensor.waqi_box_hill_australia fails
Traceback (most recent call last):
  File "/srv/homeassistant/lib/python3.4/site-packages/waqiasync/__init__.py", line 48, in _get
    path, params=dict(self._params, **kwargs))
  File "/srv/homeassistant/lib/python3.4/site-packages/aiohttp/helpers.py", line 97, in __iter__
    ret = yield from self._coro
  File "/srv/homeassistant/lib/python3.4/site-packages/aiohttp/client.py", line 231, in _request
    conn = yield from self._connector.connect(req)
  File "/srv/homeassistant/lib/python3.4/site-packages/aiohttp/connector.py", line 378, in connect
    proto = yield from self._create_connection(req)
  File "/srv/homeassistant/lib/python3.4/site-packages/aiohttp/connector.py", line 687, in _create_connection
    _, proto = yield from self._create_direct_connection(req)
  File "/srv/homeassistant/lib/python3.4/site-packages/aiohttp/connector.py", line 710, in _create_direct_connection
    local_addr=self._local_addr)
  File "/usr/lib/python3.4/asyncio/base_events.py", line 557, in create_connection
    yield from self.sock_connect(sock, address)
  File "/usr/lib/python3.4/asyncio/futures.py", line 388, in __iter__
    yield self  # This tells Task to wait for completion.
  File "/usr/lib/python3.4/asyncio/tasks.py", line 286, in _wakeup
    value = future.result()
  File "/usr/lib/python3.4/asyncio/futures.py", line 269, in result
    raise CancelledError
concurrent.futures._base.CancelledError

During handling of the above exception, another exception occurred:

Traceback (most recent call last):
  File "/srv/homeassistant/lib/python3.4/site-packages/homeassistant/helpers/entity.py", line 223, in async_update_ha_state
    yield from self.async_update()
  File "/srv/homeassistant/lib/python3.4/site-packages/homeassistant/components/sensor/waqi.py", line 167, in async_update
    result = yield from self._client.get_station_by_number(self.uid)
  File "/srv/homeassistant/lib/python3.4/site-packages/waqiasync/__init__.py", line 42, in get_station_by_number
    return (yield from self._get(FEED_NUMBER_URL.format(number)))
  File "/srv/homeassistant/lib/python3.4/site-packages/waqiasync/__init__.py", line 49, in _get
    return (yield from resp.json())['data']
  File "/srv/homeassistant/lib/python3.4/site-packages/async_timeout/__init__.py", line 36, in __exit__
    self._do_exit(exc_type)
  File "/srv/homeassistant/lib/python3.4/site-packages/async_timeout/__init__.py", line 64, in _do_exit
    raise asyncio.TimeoutError
concurrent.futures._base.TimeoutError
2018-09-21 16:06:18 ERROR (MainThread) [homeassistant.helpers.entity] Update for sensor.waqi_box_hill_australia fails
Traceback (most recent call last):
  File "/srv/homeassistant/lib/python3.4/site-packages/homeassistant/helpers/entity.py", line 223, in async_update_ha_state
    yield from self.async_update()
  File "/srv/homeassistant/lib/python3.4/site-packages/homeassistant/components/sensor/waqi.py", line 167, in async_update
    result = yield from self._client.get_station_by_number(self.uid)
  File "/srv/homeassistant/lib/python3.4/site-packages/waqiasync/__init__.py", line 42, in get_station_by_number
    return (yield from self._get(FEED_NUMBER_URL.format(number)))
  File "/srv/homeassistant/lib/python3.4/site-packages/waqiasync/__init__.py", line 49, in _get
    return (yield from resp.json())['data']
  File "/srv/homeassistant/lib/python3.4/site-packages/aiohttp/client_reqrep.py", line 730, in json
    headers=self.headers)
aiohttp.client_exceptions.ClientResponseError: 0, message='Attempt to decode JSON with unexpected mimetype: text/html'
2018-09-21 16:51:37 WARNING (Thread-17) [pychromecast.socket_client] Heartbeat timeout, resetting connection
2018-09-21 16:51:38 WARNING (Thread-21) [pychromecast.socket_client] Heartbeat timeout, resetting connection
2018-09-21 16:51:38 WARNING (Thread-20) [pychromecast.socket_client] Heartbeat timeout, resetting connection
2018-09-21 16:51:41 ERROR (Thread-21) [pychromecast.socket_client] Failed to connect, retrying in 5.0s
2018-09-21 16:51:41 ERROR (Thread-20) [pychromecast.socket_client] Failed to connect, retrying in 5.0s
2018-09-21 16:51:44 ERROR (Thread-17) [pychromecast.socket_client] Failed to connect, retrying in 5.0s
2018-09-21 17:17:34 WARNING (Thread-16) [pychromecast.socket_client] Heartbeat timeout, resetting connection
2018-09-21 17:17:35 WARNING (Thread-18) [pychromecast.socket_client] Heartbeat timeout, resetting connection
2018-09-21 17:17:35 WARNING (Thread-19) [pychromecast.socket_client] Heartbeat timeout, resetting connection
2018-09-21 17:17:49 ERROR (Thread-16) [pychromecast.socket_client] Failed to connect, retrying in 5.0s
2018-09-21 17:17:50 ERROR (Thread-18) [pychromecast.socket_client] Failed to connect, retrying in 5.0s
2018-09-21 17:17:50 ERROR (Thread-19) [pychromecast.socket_client] Failed to connect, retrying in 5.0s
2018-09-21 17:51:41 WARNING (MainThread) [homeassistant.helpers.entity] Update of sensor.waqi_box_hill_australia is taking over 10 seconds
2018-09-21 17:51:41 ERROR (MainThread) [homeassistant.helpers.entity] Update for sensor.waqi_box_hill_australia fails
Traceback (most recent call last):
  File "/srv/homeassistant/lib/python3.4/site-packages/waqiasync/__init__.py", line 48, in _get
    path, params=dict(self._params, **kwargs))
  File "/srv/homeassistant/lib/python3.4/site-packages/aiohttp/helpers.py", line 97, in __iter__
    ret = yield from self._coro
  File "/srv/homeassistant/lib/python3.4/site-packages/aiohttp/client.py", line 231, in _request
    conn = yield from self._connector.connect(req)
  File "/srv/homeassistant/lib/python3.4/site-packages/aiohttp/connector.py", line 378, in connect
    proto = yield from self._create_connection(req)
  File "/srv/homeassistant/lib/python3.4/site-packages/aiohttp/connector.py", line 687, in _create_connection
    _, proto = yield from self._create_direct_connection(req)
  File "/srv/homeassistant/lib/python3.4/site-packages/aiohttp/connector.py", line 710, in _create_direct_connection
    local_addr=self._local_addr)
  File "/usr/lib/python3.4/asyncio/base_events.py", line 557, in create_connection
    yield from self.sock_connect(sock, address)
  File "/usr/lib/python3.4/asyncio/futures.py", line 388, in __iter__
    yield self  # This tells Task to wait for completion.
  File "/usr/lib/python3.4/asyncio/tasks.py", line 286, in _wakeup
    value = future.result()
  File "/usr/lib/python3.4/asyncio/futures.py", line 269, in result
    raise CancelledError
concurrent.futures._base.CancelledError

During handling of the above exception, another exception occurred:

Traceback (most recent call last):
  File "/srv/homeassistant/lib/python3.4/site-packages/homeassistant/helpers/entity.py", line 223, in async_update_ha_state
    yield from self.async_update()
  File "/srv/homeassistant/lib/python3.4/site-packages/homeassistant/components/sensor/waqi.py", line 167, in async_update
    result = yield from self._client.get_station_by_number(self.uid)
  File "/srv/homeassistant/lib/python3.4/site-packages/waqiasync/__init__.py", line 42, in get_station_by_number
    return (yield from self._get(FEED_NUMBER_URL.format(number)))
  File "/srv/homeassistant/lib/python3.4/site-packages/waqiasync/__init__.py", line 49, in _get
    return (yield from resp.json())['data']
  File "/srv/homeassistant/lib/python3.4/site-packages/async_timeout/__init__.py", line 36, in __exit__
    self._do_exit(exc_type)
  File "/srv/homeassistant/lib/python3.4/site-packages/async_timeout/__init__.py", line 64, in _do_exit
    raise asyncio.TimeoutError
concurrent.futures._base.TimeoutError
2018-09-21 18:21:47 WARNING (MainThread) [homeassistant.helpers.entity] Update of sensor.waqi_box_hill_australia is taking over 10 seconds
2018-09-21 18:21:47 ERROR (MainThread) [homeassistant.helpers.entity] Update for sensor.waqi_box_hill_australia fails
Traceback (most recent call last):
  File "/srv/homeassistant/lib/python3.4/site-packages/waqiasync/__init__.py", line 48, in _get
    path, params=dict(self._params, **kwargs))
  File "/srv/homeassistant/lib/python3.4/site-packages/aiohttp/helpers.py", line 97, in __iter__
    ret = yield from self._coro
  File "/srv/homeassistant/lib/python3.4/site-packages/aiohttp/client.py", line 241, in _request
    yield from resp.start(conn, read_until_eof)
  File "/srv/homeassistant/lib/python3.4/site-packages/aiohttp/client_reqrep.py", line 559, in start
    (message, payload) = yield from self._protocol.read()
  File "/srv/homeassistant/lib/python3.4/site-packages/aiohttp/streams.py", line 509, in read
    yield from self._waiter
  File "/usr/lib/python3.4/asyncio/futures.py", line 388, in __iter__
    yield self  # This tells Task to wait for completion.
  File "/usr/lib/python3.4/asyncio/tasks.py", line 286, in _wakeup
    value = future.result()
  File "/usr/lib/python3.4/asyncio/futures.py", line 269, in result
    raise CancelledError
concurrent.futures._base.CancelledError

During handling of the above exception, another exception occurred:

Traceback (most recent call last):
  File "/srv/homeassistant/lib/python3.4/site-packages/homeassistant/helpers/entity.py", line 223, in async_update_ha_state
    yield from self.async_update()
  File "/srv/homeassistant/lib/python3.4/site-packages/homeassistant/components/sensor/waqi.py", line 167, in async_update
    result = yield from self._client.get_station_by_number(self.uid)
  File "/srv/homeassistant/lib/python3.4/site-packages/waqiasync/__init__.py", line 42, in get_station_by_number
    return (yield from self._get(FEED_NUMBER_URL.format(number)))
  File "/srv/homeassistant/lib/python3.4/site-packages/waqiasync/__init__.py", line 49, in _get
    return (yield from resp.json())['data']
  File "/srv/homeassistant/lib/python3.4/site-packages/async_timeout/__init__.py", line 36, in __exit__
    self._do_exit(exc_type)
  File "/srv/homeassistant/lib/python3.4/site-packages/async_timeout/__init__.py", line 64, in _do_exit
    raise asyncio.TimeoutError
concurrent.futures._base.TimeoutError
2018-09-21 18:35:59 WARNING (Thread-14) [pychromecast.socket_client] Heartbeat timeout, resetting connection
2018-09-21 18:36:00 ERROR (Thread-14) [pychromecast.socket_client] Failed to connect, retrying in 5.0s
2018-09-21 18:36:01 ERROR (Thread-13) [pychromecast.socket_client] Error reading from socket.
2018-09-21 18:36:01 WARNING (Thread-13) [pychromecast.socket_client] Error communicating with socket, resetting connection
2018-09-21 18:36:01 ERROR (Thread-15) [pychromecast.socket_client] Error reading from socket.
2018-09-21 18:36:01 WARNING (Thread-15) [pychromecast.socket_client] Error communicating with socket, resetting connection
2018-09-21 18:36:01 ERROR (Thread-13) [pychromecast.socket_client] Failed to connect, retrying in 5.0s
2018-09-21 18:36:01 ERROR (Thread-15) [pychromecast.socket_client] Failed to connect, retrying in 5.0s
2018-09-21 20:07:08 WARNING (MainThread) [homeassistant.helpers.entity] Update of sensor.waqi_box_hill_australia is taking over 10 seconds
2018-09-21 20:07:08 ERROR (MainThread) [homeassistant.helpers.entity] Update for sensor.waqi_box_hill_australia fails
Traceback (most recent call last):
  File "/srv/homeassistant/lib/python3.4/site-packages/waqiasync/__init__.py", line 48, in _get
    path, params=dict(self._params, **kwargs))
  File "/srv/homeassistant/lib/python3.4/site-packages/aiohttp/helpers.py", line 97, in __iter__
    ret = yield from self._coro
  File "/srv/homeassistant/lib/python3.4/site-packages/aiohttp/client.py", line 231, in _request
    conn = yield from self._connector.connect(req)
  File "/srv/homeassistant/lib/python3.4/site-packages/aiohttp/connector.py", line 378, in connect
    proto = yield from self._create_connection(req)
  File "/srv/homeassistant/lib/python3.4/site-packages/aiohttp/connector.py", line 687, in _create_connection
    _, proto = yield from self._create_direct_connection(req)
  File "/srv/homeassistant/lib/python3.4/site-packages/aiohttp/connector.py", line 710, in _create_direct_connection
    local_addr=self._local_addr)
  File "/usr/lib/python3.4/asyncio/base_events.py", line 557, in create_connection
    yield from self.sock_connect(sock, address)
  File "/usr/lib/python3.4/asyncio/futures.py", line 388, in __iter__
    yield self  # This tells Task to wait for completion.
  File "/usr/lib/python3.4/asyncio/tasks.py", line 286, in _wakeup
    value = future.result()
  File "/usr/lib/python3.4/asyncio/futures.py", line 269, in result
    raise CancelledError
concurrent.futures._base.CancelledError

During handling of the above exception, another exception occurred:

Traceback (most recent call last):
  File "/srv/homeassistant/lib/python3.4/site-packages/homeassistant/helpers/entity.py", line 223, in async_update_ha_state
    yield from self.async_update()
  File "/srv/homeassistant/lib/python3.4/site-packages/homeassistant/components/sensor/waqi.py", line 167, in async_update
    result = yield from self._client.get_station_by_number(self.uid)
  File "/srv/homeassistant/lib/python3.4/site-packages/waqiasync/__init__.py", line 42, in get_station_by_number
    return (yield from self._get(FEED_NUMBER_URL.format(number)))
  File "/srv/homeassistant/lib/python3.4/site-packages/waqiasync/__init__.py", line 49, in _get
    return (yield from resp.json())['data']
  File "/srv/homeassistant/lib/python3.4/site-packages/async_timeout/__init__.py", line 36, in __exit__
    self._do_exit(exc_type)
  File "/srv/homeassistant/lib/python3.4/site-packages/async_timeout/__init__.py", line 64, in _do_exit
    raise asyncio.TimeoutError
concurrent.futures._base.TimeoutError
2018-09-21 20:12:02 ERROR (MainThread) [homeassistant.helpers.entity] Update for sensor.waqi_box_hill_australia fails
Traceback (most recent call last):
  File "/srv/homeassistant/lib/python3.4/site-packages/homeassistant/helpers/entity.py", line 223, in async_update_ha_state
    yield from self.async_update()
  File "/srv/homeassistant/lib/python3.4/site-packages/homeassistant/components/sensor/waqi.py", line 167, in async_update
    result = yield from self._client.get_station_by_number(self.uid)
  File "/srv/homeassistant/lib/python3.4/site-packages/waqiasync/__init__.py", line 42, in get_station_by_number
    return (yield from self._get(FEED_NUMBER_URL.format(number)))
  File "/srv/homeassistant/lib/python3.4/site-packages/waqiasync/__init__.py", line 49, in _get
    return (yield from resp.json())['data']
  File "/srv/homeassistant/lib/python3.4/site-packages/aiohttp/client_reqrep.py", line 730, in json
    headers=self.headers)
aiohttp.client_exceptions.ClientResponseError: 0, message='Attempt to decode JSON with unexpected mimetype: text/html'
2018-09-21 20:32:13 WARNING (MainThread) [homeassistant.helpers.entity] Update of sensor.waqi_box_hill_australia is taking over 10 seconds
2018-09-21 20:32:13 ERROR (MainThread) [homeassistant.helpers.entity] Update for sensor.waqi_box_hill_australia fails
Traceback (most recent call last):
  File "/srv/homeassistant/lib/python3.4/site-packages/waqiasync/__init__.py", line 48, in _get
    path, params=dict(self._params, **kwargs))
  File "/srv/homeassistant/lib/python3.4/site-packages/aiohttp/helpers.py", line 97, in __iter__
    ret = yield from self._coro
  File "/srv/homeassistant/lib/python3.4/site-packages/aiohttp/client.py", line 231, in _request
    conn = yield from self._connector.connect(req)
  File "/srv/homeassistant/lib/python3.4/site-packages/aiohttp/connector.py", line 378, in connect
    proto = yield from self._create_connection(req)
  File "/srv/homeassistant/lib/python3.4/site-packages/aiohttp/connector.py", line 687, in _create_connection
    _, proto = yield from self._create_direct_connection(req)
  File "/srv/homeassistant/lib/python3.4/site-packages/aiohttp/connector.py", line 710, in _create_direct_connection
    local_addr=self._local_addr)
  File "/usr/lib/python3.4/asyncio/base_events.py", line 557, in create_connection
    yield from self.sock_connect(sock, address)
  File "/usr/lib/python3.4/asyncio/futures.py", line 388, in __iter__
    yield self  # This tells Task to wait for completion.
  File "/usr/lib/python3.4/asyncio/tasks.py", line 286, in _wakeup
    value = future.result()
  File "/usr/lib/python3.4/asyncio/futures.py", line 269, in result
    raise CancelledError
concurrent.futures._base.CancelledError

During handling of the above exception, another exception occurred:

Traceback (most recent call last):
  File "/srv/homeassistant/lib/python3.4/site-packages/homeassistant/helpers/entity.py", line 223, in async_update_ha_state
    yield from self.async_update()
  File "/srv/homeassistant/lib/python3.4/site-packages/homeassistant/components/sensor/waqi.py", line 167, in async_update
    result = yield from self._client.get_station_by_number(self.uid)
  File "/srv/homeassistant/lib/python3.4/site-packages/waqiasync/__init__.py", line 42, in get_station_by_number
    return (yield from self._get(FEED_NUMBER_URL.format(number)))
  File "/srv/homeassistant/lib/python3.4/site-packages/waqiasync/__init__.py", line 49, in _get
    return (yield from resp.json())['data']
  File "/srv/homeassistant/lib/python3.4/site-packages/async_timeout/__init__.py", line 36, in __exit__
    self._do_exit(exc_type)
  File "/srv/homeassistant/lib/python3.4/site-packages/async_timeout/__init__.py", line 64, in _do_exit
    raise asyncio.TimeoutError
concurrent.futures._base.TimeoutError
